<?xml version="1.0" encoding="UTF-8"?>
<testng-results skipped="0" failed="1" total="3" passed="2">
  <reporter-output>
  </reporter-output>
  <suite name="Default suite" duration-ms="1145" started-at="2017-08-03T04:03:31Z" finished-at="2017-08-03T04:03:32Z">
    <groups>
    </groups>
    <test name="Default test" duration-ms="1145" started-at="2017-08-03T04:03:31Z" finished-at="2017-08-03T04:03:32Z">
      <class name="meibanTestNG.NewTestNG">
        <test-method status="FAIL" signature="addAttend()[pri:0, instance:meibanTestNG.NewTestNG@656d2378]" name="addAttend" duration-ms="493" started-at="2017-08-03T12:03:31Z" finished-at="2017-08-03T12:03:31Z">
          <exception class="java.lang.AssertionError">
            <message>
              <![CDATA[MESSage expected [2] but found [1]]]>
            </message>
            <full-stacktrace>
              <![CDATA[java.lang.AssertionError: MESSage expected [2] but found [1]
	at org.testng.Assert.fail(Assert.java:94)
	at org.testng.Assert.failNotEquals(Assert.java:496)
	at org.testng.Assert.assertEquals(Assert.java:125)
	at org.testng.Assert.assertEquals(Assert.java:372)
	at meibanTestNG.NewTestNG.addAttend(NewTestNG.java:58)
	at meibanTestNG.NewTestNG.addAttend(NewTestNG.java:16)
	at sun.reflect.NativeMethodAccessorImpl.invoke0(Native Method)
	at sun.reflect.NativeMethodAccessorImpl.invoke(Unknown Source)
	at sun.reflect.DelegatingMethodAccessorImpl.invoke(Unknown Source)
	at java.lang.reflect.Method.invoke(Unknown Source)
	at org.testng.internal.MethodInvocationHelper.invokeMethod(MethodInvocationHelper.java:85)
	at org.testng.internal.Invoker.invokeMethod(Invoker.java:639)
	at org.testng.internal.Invoker.invokeTestMethod(Invoker.java:816)
	at org.testng.internal.Invoker.invokeTestMethods(Invoker.java:1124)
	at org.testng.internal.TestMethodWorker.invokeTestMethods(TestMethodWorker.java:125)
	at org.testng.internal.TestMethodWorker.run(TestMethodWorker.java:108)
	at org.testng.TestRunner.privateRun(TestRunner.java:774)
	at org.testng.TestRunner.run(TestRunner.java:624)
	at org.testng.SuiteRunner.runTest(SuiteRunner.java:359)
	at org.testng.SuiteRunner.runSequentially(SuiteRunner.java:354)
	at org.testng.SuiteRunner.privateRun(SuiteRunner.java:312)
	at org.testng.SuiteRunner.run(SuiteRunner.java:261)
	at org.testng.SuiteRunnerWorker.runSuite(SuiteRunnerWorker.java:52)
	at org.testng.SuiteRunnerWorker.run(SuiteRunnerWorker.java:86)
	at org.testng.TestNG.runSuitesSequentially(TestNG.java:1191)
	at org.testng.TestNG.runSuitesLocally(TestNG.java:1116)
	at org.testng.TestNG.run(TestNG.java:1024)
	at org.testng.remote.RemoteTestNG.run(RemoteTestNG.java:112)
	at org.testng.remote.RemoteTestNG.initAndRun(RemoteTestNG.java:205)
	at org.testng.remote.RemoteTestNG.main(RemoteTestNG.java:176)
]]>
            </full-stacktrace>
          </exception> <!-- java.lang.AssertionError -->
          <reporter-output>
          </reporter-output>
        </test-method> <!-- addAttend -->
        <test-method status="PASS" signature="initAtdAddress()[pri:0, instance:meibanTestNG.NewTestNG@656d2378]" name="initAtdAddress" duration-ms="91" started-at="2017-08-03T12:03:31Z" finished-at="2017-08-03T12:03:31Z">
          <reporter-output>
          </reporter-output>
        </test-method> <!-- initAtdAddress -->
        <test-method status="PASS" signature="listAtdRecord()[pri:0, instance:meibanTestNG.NewTestNG@656d2378]" name="listAtdRecord" duration-ms="535" started-at="2017-08-03T12:03:31Z" finished-at="2017-08-03T12:03:32Z">
          <reporter-output>
          </reporter-output>
        </test-method> <!-- listAtdRecord -->
      </class> <!-- meibanTestNG.NewTestNG -->
    </test> <!-- Default test -->
  </suite> <!-- Default suite -->
</testng-results>
