<?xml version="1.0" encoding="UTF-8"?>
<testsuite name="Test"
           tests="8"
           failures="2"
           errors="0"
           skipped="0"
           time="0.577">
    <properties/>
    <testcase name="doApproveTask8" time="0.101" classname="meibanApprove.doApproveTask">
        <failure type="java.lang.AssertionError"
                 message="202032 StateMessage:�ǵ�ǰ�������޷����в��� expected [0] but found [202032]"
        >
            <![CDATA[java.lang.AssertionError: 202032 StateMessage:�ǵ�ǰ�������޷����в��� expected [0] but found [202032]
  org.testng.Assert.fail(Assert.java:94)
  org.testng.Assert.failNotEquals(Assert.java:496)
  org.testng.Assert.assertEquals(Assert.java:125)
  org.testng.Assert.assertEquals(Assert.java:372)
  meibanApprove.doApproveTask.doApproveTask8(doApproveTask.java:191)
  sun.reflect.NativeMethodAccessorImpl.invoke0(Native Method)
  sun.reflect.NativeMethodAccessorImpl.invoke(Unknown Source)
  sun.reflect.DelegatingMethodAccessorImpl.invoke(Unknown Source)
  java.lang.reflect.Method.invoke(Unknown Source)
  org.testng.internal.MethodInvocationHelper.invokeMethod(MethodInvocationHelper.java:85)
  org.testng.internal.Invoker.invokeMethod(Invoker.java:639)
  org.testng.internal.Invoker.invokeTestMethod(Invoker.java:816)
  org.testng.internal.Invoker.invokeTestMethods(Invoker.java:1124)
  org.testng.internal.TestMethodWorker.invokeTestMethods(TestMethodWorker.java:125)
  org.testng.internal.TestMethodWorker.run(TestMethodWorker.java:108)
  org.testng.TestRunner.privateRun(TestRunner.java:774)
  org.testng.TestRunner.run(TestRunner.java:624)
  org.testng.SuiteRunner.runTest(SuiteRunner.java:359)
  org.testng.SuiteRunner.runSequentially(SuiteRunner.java:354)
  org.testng.SuiteRunner.privateRun(SuiteRunner.java:312)
  org.testng.SuiteRunner.run(SuiteRunner.java:261)
  org.testng.SuiteRunnerWorker.runSuite(SuiteRunnerWorker.java:52)
  org.testng.SuiteRunnerWorker.run(SuiteRunnerWorker.java:86)
  org.testng.TestNG.runSuitesSequentially(TestNG.java:1191)
  org.testng.TestNG.runSuitesLocally(TestNG.java:1116)
  org.testng.TestNG.run(TestNG.java:1024)
  org.testng.remote.RemoteTestNG.run(RemoteTestNG.java:112)
  org.testng.remote.RemoteTestNG.initAndRun(RemoteTestNG.java:205)
  org.testng.remote.RemoteTestNG.main(RemoteTestNG.java:176)
]]>
        </failure>

    </testcase>
    <testcase name="doApproveTask7" time="0.129" classname="meibanApprove.doApproveTask">
        <failure type="java.lang.AssertionError"
                 message="202016 StateMessage:�����뵥�ѳ��������޷������鿴 expected [0] but found [202016]"
        >
            <![CDATA[java.lang.AssertionError: 202016 StateMessage:�����뵥�ѳ��������޷������鿴 expected [0] but found [202016]
  org.testng.Assert.fail(Assert.java:94)
  org.testng.Assert.failNotEquals(Assert.java:496)
  org.testng.Assert.assertEquals(Assert.java:125)
  org.testng.Assert.assertEquals(Assert.java:372)
  meibanApprove.doApproveTask.doApproveTask7(doApproveTask.java:168)
  sun.reflect.NativeMethodAccessorImpl.invoke0(Native Method)
  sun.reflect.NativeMethodAccessorImpl.invoke(Unknown Source)
  sun.reflect.DelegatingMethodAccessorImpl.invoke(Unknown Source)
  java.lang.reflect.Method.invoke(Unknown Source)
  org.testng.internal.MethodInvocationHelper.invokeMethod(MethodInvocationHelper.java:85)
  org.testng.internal.Invoker.invokeMethod(Invoker.java:639)
  org.testng.internal.Invoker.invokeTestMethod(Invoker.java:816)
  org.testng.internal.Invoker.invokeTestMethods(Invoker.java:1124)
  org.testng.internal.TestMethodWorker.invokeTestMethods(TestMethodWorker.java:125)
  org.testng.internal.TestMethodWorker.run(TestMethodWorker.java:108)
  org.testng.TestRunner.privateRun(TestRunner.java:774)
  org.testng.TestRunner.run(TestRunner.java:624)
  org.testng.SuiteRunner.runTest(SuiteRunner.java:359)
  org.testng.SuiteRunner.runSequentially(SuiteRunner.java:354)
  org.testng.SuiteRunner.privateRun(SuiteRunner.java:312)
  org.testng.SuiteRunner.run(SuiteRunner.java:261)
  org.testng.SuiteRunnerWorker.runSuite(SuiteRunnerWorker.java:52)
  org.testng.SuiteRunnerWorker.run(SuiteRunnerWorker.java:86)
  org.testng.TestNG.runSuitesSequentially(TestNG.java:1191)
  org.testng.TestNG.runSuitesLocally(TestNG.java:1116)
  org.testng.TestNG.run(TestNG.java:1024)
  org.testng.remote.RemoteTestNG.run(RemoteTestNG.java:112)
  org.testng.remote.RemoteTestNG.initAndRun(RemoteTestNG.java:205)
  org.testng.remote.RemoteTestNG.main(RemoteTestNG.java:176)
]]>
        </failure>

    </testcase>


    <testcase name="doApproveTask5" time="0.032" classname="meibanApprove.doApproveTask"/>
    <testcase name="doApproveTask2" time="0.033" classname="meibanApprove.doApproveTask"/>
    <testcase name="doApproveTask3" time="0.034" classname="meibanApprove.doApproveTask"/>
    <testcase name="doApproveTask" time="0.180" classname="meibanApprove.doApproveTask"/>
    <testcase name="doApproveTask4" time="0.033" classname="meibanApprove.doApproveTask"/>
    <testcase name="doApproveTask6" time="0.035" classname="meibanApprove.doApproveTask"/>

</testsuite>
